实例
无论 try 块是否引发错误，都将始终执行 finally 块：
try:
  x > 3
except:
  print("Something went wrong")
else:
  print("Nothing went wrong")
finally:
  print("The try...except block is finished")
追加函数!
追加函数!
实验!